<?xml version="1.0" ?>
<!-- =================================================================================== -->
<!-- |    This document was autogenerated by xacro from quadruped.urdf.xacro           | -->
<!-- |    EDITING THIS FILE BY HAND IS NOT RECOMMENDED                                 | -->
<!-- =================================================================================== -->
<robot name="quadruped" xmlns:xacro="http://ros.org/wiki/xacro">
  <!-- Colour -->
  <material name="black">
    <color rgba="0.0 0.0 0.0 1.0"/>
  </material>
  <material name="red">
    <color rgba="0.8 0.0 0.0 1.0"/>
  </material>
  <material name="white">
    <color rgba="1.0 1.0 1.0 1.0"/>
  </material>
  <!-- pelvis height-->
  <!-- radius of the cylinder-->
  <!-- radius of the cylinder-->
  <!-- radius of the cylinder-->
  <!--radius of the leg above the knee-->
  <!-- knee cylinder radius-->
  <!-- radius below the knee -->
  <!-- //////////////////////////Upper body parameters///////////////////////-->
  <gazebo>
    <plugin filename="libgazebo_ros_control.so" name="gazebo_ros_control">
      <robotNamespace>/quadruped/</robotNamespace>
      <robotSimType>gazebo_ros_control/DefaultRobotHWSim</robotSimType>
    </plugin>
  </gazebo>
  <!-- Things that are needed only for Gazebo (not the physical robot). These include sensor and controller plugin specifications
	<xacro:include filename="$(find quadruped_description)/urdfs/trunk/trunk.gazebo.xacro"/>-->
  <!-- Things that are needed only for Gazebo (not the physical robot). These include sensor and controller plugin specifications
	<xacro:include filename="$(find quadruped_description)/urdfs/trunk/trunk.gazebo.xacro"/>-->
  <!-- generic simulator_gazebo plugins for starting mechanism control, ros time
	<xacro:include filename="$(find quadruped_description)/gazebo/gazebo.urdf.xacro"/>-->
  <!-- Now we can start using the macros included above to define the actual HyQ -->
  <!-- The first use of a macro. This one was defined in trunk.urdf.xacro above.
A macro like this will expand to a set of link and joint definitions, and to additional
Gazebo-related extensions (sensor plugins, etc). The macro takes an argument, name,
that equals "base", and uses it to generate names for its component links and joints
(e.g., base_link). The included origin block is also an argument to the macro. By convention,
the origin block defines where the component is w.r.t its parent (in this case the parent
is the world frame). For more, see http://ros.org/wiki/xacro -->
  <!-- Floating-base Joint -->
  <joint name="base_footprint_joint" type="fixed">
    <origin rpy="0 0 0" xyz="0 0 0"/>
    <parent link="base_footprint"/>
    <child link="pelvis"/>
  </joint>
  <!-- Links -->
  <!-- Footprint link -->
  <link name="base_footprint">
    <visual>
      <origin rpy="0 0 0" xyz="0 0 0"/>
      <geometry>
        <box size="0.001 0.001 0.001"/>
      </geometry>
    </visual>
  </link>
  <!-- Trunk link -->
  <link name="pelvis">
    <inertial>
      <mass value="60.96"/>
      <origin xyz="0.056 0.0215 0.00358"/>
      <inertia ixx="1.572" ixy="0.028" ixz="-0.203" iyy="8.502" iyz="-0.004" izz="9.195"/>
    </inertial>
    <visual>
      <geometry>
        <box size="2.0 1.2 0.5"/>
      </geometry>
      <origin rpy="0 0 0" xyz="0 0 0"/>
      <material name="red"/>
    </visual>
    <collision>
      <geometry>
        <box size="2.0 1.2 0.5"/>
      </geometry>
    </collision>
  </link>
  <gazebo reference="pelvis">
    <mu1>1.5</mu1>
    <mu2>1.5</mu2>
  </gazebo>
  <!--Joints-->
  <!-- joint between the thigh_roll_cylinder and pelvic -->
  <joint name="forward_right_thigh_roll_joint" type="revolute">
    <origin xyz="0.7 -0.68 -0.1"/>
    <!-- 0.3 and 0.1 are the offset provided for the thigh_roll_cylinder from the front and centerline below-->
    <parent link="pelvis"/>
    <child link="forward_right_thigh_roll_cylinder"/>
    <axis xyz="1 0 0"/>
    <limit effort="300" lower="-1.0471975512" upper="0.261799387799" velocity="0.1"/>
    <dynamics damping="0.1" friction="0"/>
  </joint>
  <!-- fixed joint between the thigh_roll_cylinder and thigh_bwn_cylinder -->
  <joint name="forward_right_thigh_bwn_joint" type="fixed">
    <origin xyz="0 0 -0.115"/>
    <parent link="forward_right_thigh_roll_cylinder"/>
    <child link="forward_right_thigh_bwn_cylinder"/>
  </joint>
  <!-- the joint which allows the pitch motion of the thigh -->
  <joint name="forward_right_thigh_pitch_joint" type="revolute">
    <origin rpy="0 0.523598775598 0" xyz="0 0 -0.095"/>
    <parent link="forward_right_thigh_bwn_cylinder"/>
    <child link="forward_right_thigh_pitch_cylinder"/>
    <axis xyz="0 1 0"/>
    <limit effort="300" lower="-1.5707963268" upper="0.523598775598" velocity="0.1"/>
    <dynamics damping="0.1" friction="0"/>
  </joint>
  <!-- the permanent joint connecting upper leg and the thigh_pitch_cylinder -->
  <joint name="forward_right_leg_thigh_joint" type="fixed">
    <origin xyz="0 0 -0.41"/>
    <parent link="forward_right_thigh_pitch_cylinder"/>
    <child link="forward_right_upper_leg"/>
  </joint>
  <!-- knee joint -->
  <joint name="forward_right_knee_joint" type="revolute">
    <origin rpy="0 -1.308996939 0" xyz="0 0 -0.41"/>
    <parent link="forward_right_upper_leg"/>
    <child link="forward_right_knee_cylinder"/>
    <axis xyz="0 1 0"/>
    <limit effort="300" lower="-0.698131700798" upper="2.61799387799" velocity="0.1"/>
    <dynamics damping="0.1" friction="0"/>
  </joint>
  <!-- the permanent joint connecting the knee cylinder with the lower leg -->
  <joint name="forward_right_knee_fixed_joint" type="fixed">
    <origin xyz="0 0 -0.36"/>
    <parent link="forward_right_knee_cylinder"/>
    <child link="forward_right_lower_leg"/>
  </joint>
  <!-- the permanent joint connecting the sole and lower_leg -->
  <joint name="forward_right_sole_fixed_joint" type="fixed">
    <origin xyz="0 0 -0.37"/>
    <parent link="forward_right_lower_leg"/>
    <child link="forward_right_sole_sphere"/>
  </joint>
  <!-- Links -->
  <!--- link which allows the lateral motion of the link -->
  <link name="forward_right_thigh_roll_cylinder">
    <inertial>
      <mass value="0.1"/>
      <origin xyz="0 0 0"/>
      <inertia ixx="3.99988e-05" ixy="0" ixz="0" iyy="2e-05" iyz="0" izz="3.99988e-05"/>
    </inertial>
    <visual>
      <geometry>
        <cylinder length="0.2" radius="0.08"/>
      </geometry>
      <origin rpy="0 1.57079632679 0" xyz="0 0 0"/>
      <material name="red"/>
    </visual>
    <collision>
      <origin rpy="0 1.57079632679 0" xyz="0 0 0"/>
      <geometry>
        <cylinder length="0.2" radius="0.08"/>
      </geometry>
    </collision>
  </link>
  <!--- the link which joints the thigh_roll_cylinder and thigh_pitch_cylinder -->
  <link name="forward_right_thigh_bwn_cylinder">
    <inertial>
      <mass value="0.1"/>
      <origin xyz="0 0 0"/>
      <inertia ixx="3.99988e-05" ixy="0" ixz="0" iyy="3.99988e-05" iyz="0" izz="2e-05"/>
    </inertial>
    <visual>
      <geometry>
        <cylinder length="0.07" radius="0.03"/>
      </geometry>
      <origin xyz="0 0 0"/>
      <material name="red"/>
    </visual>
    <collision>
      <geometry>
        <cylinder length="0.07" radius="0.03"/>
      </geometry>
    </collision>
  </link>
  <!-- the link(cylinder) which is attached to the upper_leg -->
  <link name="forward_right_thigh_pitch_cylinder">
    <inertial>
      <mass value="0.1"/>
      <origin xyz="0 0 0"/>
      <inertia ixx="2e-05" ixy="0" ixz="0" iyy="3.99988e-05" iyz="0" izz="3.99988e-05"/>
    </inertial>
    <visual>
      <geometry>
        <cylinder length="0.2" radius="0.06"/>
      </geometry>
      <origin rpy="1.57079632679 0 0" xyz="0 0 0"/>
      <material name="red"/>
    </visual>
    <collision>
      <origin rpy="1.57079632679 0 0" xyz="0 0 0"/>
      <geometry>
        <cylinder length="0.2" radius="0.06"/>
      </geometry>
    </collision>
  </link>
  <!-- the upper leg -->
  <link name="forward_right_upper_leg">
    <inertial>
      <mass value="2.638"/>
      <origin xyz="0.150 0.026 0.0"/>
      <inertia ixx="0.0036" ixy="-0.003" ixz="0.0001" iyy="0.027" iyz="0.00002" izz="0.028"/>
    </inertial>
    <visual>
      <geometry>
        <cylinder length="0.7" radius="0.075"/>
      </geometry>
      <origin rpy="0 0 0" xyz="0 0 0"/>
      <material name="red"/>
    </visual>
    <collision>
      <geometry>
        <cylinder length="0.7" radius="0.075"/>
      </geometry>
    </collision>
  </link>
  <!-- the link(cylinder) at the knee which connects the upper and lower leg -->
  <link name="forward_right_knee_cylinder">
    <inertial>
      <mass value="0.1"/>
      <origin xyz="0 0 0"/>
      <inertia ixx="2e-05" ixy="0" ixz="0" iyy="3.99988e-05" iyz="0" izz="3.99988e-05"/>
    </inertial>
    <visual>
      <geometry>
        <cylinder length="0.2" radius="0.06"/>
      </geometry>
      <origin rpy="1.57079632679 0 0" xyz="0 0 0"/>
      <material name="red"/>
    </visual>
    <collision>
      <origin rpy="1.57079632679 0 0" xyz="0 0 0"/>
      <geometry>
        <cylinder length="0.2" radius="0.06"/>
      </geometry>
    </collision>
  </link>
  <!-- lower leg -->
  <link name="forward_right_lower_leg">
    <inertial>
      <mass value="0.881"/>
      <origin xyz="0.125 0.00004 -0.0001"/>
      <inertia ixx="0.0125" ixy="0.00006" ixz="-0.00001" iyy="0.01256" iyz="0" izz="0.0123"/>
    </inertial>
    <visual>
      <geometry>
        <cylinder length="0.6" radius="0.06"/>
      </geometry>
      <origin rpy="0 0 0" xyz="0 0 0"/>
      <material name="red"/>
    </visual>
    <collision>
      <geometry>
        <cylinder length="0.6" radius="0.06"/>
      </geometry>
    </collision>
  </link>
  <!-- the sphere which acts as the sole of the robot -->
  <link name="forward_right_sole_sphere">
    <inertial>
      <mass value="0.1"/>
      <origin xyz="0 0 0"/>
      <inertia ixx="1.6e-05" ixy="0" ixz="0" iyy="1.6e-05" iyz="0" izz="1.6e-05"/>
    </inertial>
    <visual>
      <geometry>
        <sphere radius="0.09"/>
      </geometry>
      <origin rpy="0 0 0" xyz="0 0 0"/>
      <material name="red"/>
    </visual>
    <collision>
      <geometry>
        <sphere radius="0.09"/>
      </geometry>
    </collision>
  </link>
  <!-- Hip assembly -->
  <transmission name="forward_right_thigh_roll_trans">
    <type>transmission_interface/SimpleTransmission</type>
    <joint name="forward_right_thigh_roll_joint">
      <hardwareInterface>hardware_interface/EffortJointInterface</hardwareInterface>
    </joint>
    <actuator name="forward_right_thigh_roll_motor">
      <hardwareInterface>hardware_interface/EffortJointInterface</hardwareInterface>
      <mechanicalReduction>1</mechanicalReduction>
    </actuator>
  </transmission>
  <!-- Upper leg -->
  <transmission name="forward_right_thigh_pitch_trans">
    <type>transmission_interface/SimpleTransmission</type>
    <joint name="forward_right_thigh_pitch_joint">
      <hardwareInterface>hardware_interface/EffortJointInterface</hardwareInterface>
    </joint>
    <actuator name="forward_right_thigh_pitch_motor">
      <hardwareInterface>hardware_interface/EffortJointInterface</hardwareInterface>
      <mechanicalReduction>1</mechanicalReduction>
    </actuator>
  </transmission>
  <!-- Lower leg -->
  <transmission name="forward_right_knee_trans">
    <type>transmission_interface/SimpleTransmission</type>
    <joint name="forward_right_knee_joint">
      <hardwareInterface>hardware_interface/EffortJointInterface</hardwareInterface>
    </joint>
    <actuator name="forward_right_knee_motor">
      <hardwareInterface>hardware_interface/EffortJointInterface</hardwareInterface>
      <mechanicalReduction>1</mechanicalReduction>
    </actuator>
  </transmission>
  <gazebo reference="forward_right_thigh_roll_joint">
    <provideFeedback>true</provideFeedback>
    <material>Gazebo/White</material>
  </gazebo>
  <gazebo>
    <plugin filename="libgazebo_ros_ft_sensor.so" name="forward_right_thigh_roll_joint">
      <robotNamespace>/quadruped/internal_wrench/</robotNamespace>
      <updateRate>100.0</updateRate>
      <topicName>forward_right_thigh_roll_joint</topicName>
      <jointName>forward_right_thigh_roll_joint</jointName>
    </plugin>
  </gazebo>
  <gazebo reference="forward_right_thigh_pitch_joint">
    <provideFeedback>true</provideFeedback>
    <material>Gazebo/White</material>
  </gazebo>
  <gazebo>
    <plugin filename="libgazebo_ros_ft_sensor.so" name="forward_right_thigh_pitch_joint">
      <robotNamespace>/quadruped/internal_wrench/</robotNamespace>
      <updateRate>100.0</updateRate>
      <topicName>forward_right_thigh_pitch_joint</topicName>
      <jointName>forward_right_thigh_pitch_joint</jointName>
    </plugin>
  </gazebo>
  <gazebo reference="forward_right_knee_joint">
    <provideFeedback>true</provideFeedback>
    <material>Gazebo/White</material>
  </gazebo>
  <gazebo>
    <plugin filename="libgazebo_ros_ft_sensor.so" name="forward_right_knee_joint">
      <robotNamespace>/quadruped/internal_wrench/</robotNamespace>
      <updateRate>100.0</updateRate>
      <topicName>forward_right_knee_joint</topicName>
      <jointName>forward_right_knee_joint</jointName>
    </plugin>
  </gazebo>
  <gazebo reference="forward_right_upper_leg">
    <kp>1000000.0</kp>
    <kd>100.0</kd>
    <mu1>1.5</mu1>
    <mu2>1.5</mu2>
    <fdir1>1 0 0</fdir1>
    <maxVel>1.0</maxVel>
    <minDepth>0.00</minDepth>
    <material>Gazebo/White</material>
  </gazebo>
  <gazebo reference="forward_right_lower_leg">
    <kp>1000000.0</kp>
    <kd>100.0</kd>
    <mu1>1.0</mu1>
    <mu2>1.0</mu2>
    <maxVel>1.0</maxVel>
    <maxContacts>1</maxContacts>
    <sensor name="forward_right_shin_contact_sensor" type="contact">
      <always_on>true</always_on>
      <update_rate>250.0</update_rate>
      <contact>
        <collision>forward_right_lowerleg_collision</collision>
      </contact>
      <plugin filename="libgazebo_ros_bumper.so" name="forward_right_shin_bumper">
        <bumperTopicName>/quadruped/forward_right_shin_bumper</bumperTopicName>
        <frameName>base_footprint</frameName>
      </plugin>
    </sensor>
    <material>Gazebo/White</material>
  </gazebo>
  <gazebo reference="forward_right_sole_sphere">
    <kp>1000000.0</kp>
    <kd>100.0</kd>
    <mu1>1.0</mu1>
    <mu2>1.0</mu2>
    <maxVel>1.0</maxVel>
    <maxContacts>1</maxContacts>
    <sensor name="forward_right_foot_contact_sensor" type="contact">
      <always_on>true</always_on>
      <update_rate>250.0</update_rate>
      <contact>
        <collision>forward_right_lowerleg_fixed_joint_lump__forward_right_foot_collision_1</collision>
      </contact>
      <plugin filename="libgazebo_ros_bumper.so" name="forward_right_foot_bumper">
        <bumperTopicName>/quadruped/forward_right_foot_bumper</bumperTopicName>
        <frameName>base_footprint</frameName>
        <robotNamespace>quadruped</robotNamespace>
      </plugin>
    </sensor>
    <material>Gazebo/White</material>
  </gazebo>
  <!--Joints-->
  <!-- joint between the thigh_roll_cylinder and pelvic -->
  <joint name="forward_left_thigh_roll_joint" type="revolute">
    <origin xyz="0.7 0.68 -0.1"/>
    <!-- 0.3 and 0.1 are the offset provided for the thigh_roll_cylinder from the front and centerline below-->
    <parent link="pelvis"/>
    <child link="forward_left_thigh_roll_cylinder"/>
    <axis xyz="1 0 0"/>
    <limit effort="300" lower="-0.261799387799" upper="1.0471975512" velocity="0.1"/>
    <dynamics damping="0.1" friction="0"/>
  </joint>
  <!-- fixed joint between the thigh_roll_cylinder and thigh_bwn_cylinder -->
  <joint name="forward_left_thigh_bwn_joint" type="fixed">
    <origin xyz="0 0 -0.115"/>
    <parent link="forward_left_thigh_roll_cylinder"/>
    <child link="forward_left_thigh_bwn_cylinder"/>
  </joint>
  <!-- the joint which allows the pitch motion of the thigh -->
  <joint name="forward_left_thigh_pitch_joint" type="revolute">
    <origin rpy="0 0.523598775598 0" xyz="0 0 -0.095"/>
    <parent link="forward_left_thigh_bwn_cylinder"/>
    <child link="forward_left_thigh_pitch_cylinder"/>
    <axis xyz="0 1 0"/>
    <limit effort="300" lower="-1.5707963268" upper="0.523598775598" velocity="0.1"/>
    <dynamics damping="0.1" friction="0"/>
  </joint>
  <!-- the permanent joint connecting upper leg and the thigh_pitch_cylinder -->
  <joint name="forward_left_leg_thigh_joint" type="fixed">
    <origin xyz="0 0 -0.41"/>
    <parent link="forward_left_thigh_pitch_cylinder"/>
    <child link="forward_left_upper_leg"/>
  </joint>
  <!-- knee joint -->
  <joint name="forward_left_knee_joint" type="revolute">
    <origin rpy="0 -1.308996939 0" xyz="0 0 -0.41"/>
    <parent link="forward_left_upper_leg"/>
    <child link="forward_left_knee_cylinder"/>
    <axis xyz="0 1 0"/>
    <limit effort="300" lower="-0.698131700798" upper="2.61799387799" velocity="0.1"/>
    <dynamics damping="0.1" friction="0"/>
  </joint>
  <!-- the permanent joint connecting the knee cylinder with the lower leg -->
  <joint name="forward_left_knee_fixed_joint" type="fixed">
    <origin xyz="0 0 -0.36"/>
    <parent link="forward_left_knee_cylinder"/>
    <child link="forward_left_lower_leg"/>
  </joint>
  <!-- the permanent joint connecting the sole and lower_leg -->
  <joint name="forward_left_sole_fixed_joint" type="fixed">
    <origin xyz="0 0 -0.37"/>
    <parent link="forward_left_lower_leg"/>
    <child link="forward_left_sole_sphere"/>
  </joint>
  <!-- Links -->
  <!--- link which allows the lateral motion of the link -->
  <link name="forward_left_thigh_roll_cylinder">
    <inertial>
      <mass value="0.1"/>
      <origin xyz="0 0 0"/>
      <inertia ixx="3.99988e-05" ixy="0" ixz="0" iyy="2e-05" iyz="0" izz="3.99988e-05"/>
    </inertial>
    <visual>
      <geometry>
        <cylinder length="0.2" radius="0.08"/>
      </geometry>
      <origin rpy="0 1.57079632679 0" xyz="0 0 0"/>
      <material name="red"/>
    </visual>
    <collision>
      <origin rpy="0 1.57079632679 0" xyz="0 0 0"/>
      <geometry>
        <cylinder length="0.2" radius="0.08"/>
      </geometry>
    </collision>
  </link>
  <!--- the link which joints the thigh_roll_cylinder and thigh_pitch_cylinder -->
  <link name="forward_left_thigh_bwn_cylinder">
    <inertial>
      <mass value="0.1"/>
      <origin xyz="0 0 0"/>
      <inertia ixx="3.99988e-05" ixy="0" ixz="0" iyy="3.99988e-05" iyz="0" izz="2e-05"/>
    </inertial>
    <visual>
      <geometry>
        <cylinder length="0.07" radius="0.03"/>
      </geometry>
      <origin xyz="0 0 0"/>
      <material name="red"/>
    </visual>
    <collision>
      <geometry>
        <cylinder length="0.07" radius="0.03"/>
      </geometry>
    </collision>
  </link>
  <!-- the link(cylinder) which is attached to the upper_leg -->
  <link name="forward_left_thigh_pitch_cylinder">
    <inertial>
      <mass value="0.1"/>
      <origin xyz="0 0 0"/>
      <inertia ixx="2e-05" ixy="0" ixz="0" iyy="3.99988e-05" iyz="0" izz="3.99988e-05"/>
    </inertial>
    <visual>
      <geometry>
        <cylinder length="0.2" radius="0.06"/>
      </geometry>
      <origin rpy="1.57079632679 0 0" xyz="0 0 0"/>
      <material name="red"/>
    </visual>
    <collision>
      <origin rpy="1.57079632679 0 0" xyz="0 0 0"/>
      <geometry>
        <cylinder length="0.2" radius="0.06"/>
      </geometry>
    </collision>
  </link>
  <!-- the upper leg -->
  <link name="forward_left_upper_leg">
    <inertial>
      <mass value="2.638"/>
      <origin xyz="0.150 0.026 0.0"/>
      <inertia ixx="0.0036" ixy="-0.003" ixz="0.0001" iyy="0.027" iyz="0.00002" izz="0.028"/>
    </inertial>
    <visual>
      <geometry>
        <cylinder length="0.7" radius="0.075"/>
      </geometry>
      <origin rpy="0 0 0" xyz="0 0 0"/>
      <material name="red"/>
    </visual>
    <collision>
      <geometry>
        <cylinder length="0.7" radius="0.075"/>
      </geometry>
    </collision>
  </link>
  <!-- the link(cylinder) at the knee which connects the upper and lower leg -->
  <link name="forward_left_knee_cylinder">
    <inertial>
      <mass value="0.1"/>
      <origin xyz="0 0 0"/>
      <inertia ixx="2e-05" ixy="0" ixz="0" iyy="3.99988e-05" iyz="0" izz="3.99988e-05"/>
    </inertial>
    <visual>
      <geometry>
        <cylinder length="0.2" radius="0.06"/>
      </geometry>
      <origin rpy="1.57079632679 0 0" xyz="0 0 0"/>
      <material name="red"/>
    </visual>
    <collision>
      <origin rpy="1.57079632679 0 0" xyz="0 0 0"/>
      <geometry>
        <cylinder length="0.2" radius="0.06"/>
      </geometry>
    </collision>
  </link>
  <!-- lower leg -->
  <link name="forward_left_lower_leg">
    <inertial>
      <mass value="0.881"/>
      <origin xyz="0.125 0.00004 -0.0001"/>
      <inertia ixx="0.0125" ixy="0.00006" ixz="-0.00001" iyy="0.01256" iyz="0" izz="0.0123"/>
    </inertial>
    <visual>
      <geometry>
        <cylinder length="0.6" radius="0.06"/>
      </geometry>
      <origin rpy="0 0 0" xyz="0 0 0"/>
      <material name="red"/>
    </visual>
    <collision>
      <geometry>
        <cylinder length="0.6" radius="0.06"/>
      </geometry>
    </collision>
  </link>
  <!-- the sphere which acts as the sole of the robot -->
  <link name="forward_left_sole_sphere">
    <inertial>
      <mass value="0.1"/>
      <origin xyz="0 0 0"/>
      <inertia ixx="1.6e-05" ixy="0" ixz="0" iyy="1.6e-05" iyz="0" izz="1.6e-05"/>
    </inertial>
    <visual>
      <geometry>
        <sphere radius="0.09"/>
      </geometry>
      <origin rpy="0 0 0" xyz="0 0 0"/>
      <material name="red"/>
    </visual>
    <collision>
      <geometry>
        <sphere radius="0.09"/>
      </geometry>
    </collision>
  </link>
  <!-- Hip assembly -->
  <transmission name="forward_left_thigh_roll_trans">
    <type>transmission_interface/SimpleTransmission</type>
    <joint name="forward_left_thigh_roll_joint">
      <hardwareInterface>hardware_interface/EffortJointInterface</hardwareInterface>
    </joint>
    <actuator name="forward_left_thigh_roll_motor">
      <hardwareInterface>hardware_interface/EffortJointInterface</hardwareInterface>
      <mechanicalReduction>1</mechanicalReduction>
    </actuator>
  </transmission>
  <!-- Upper leg -->
  <transmission name="forward_left_thigh_pitch_trans">
    <type>transmission_interface/SimpleTransmission</type>
    <joint name="forward_left_thigh_pitch_joint">
      <hardwareInterface>hardware_interface/EffortJointInterface</hardwareInterface>
    </joint>
    <actuator name="forward_left_thigh_pitch_motor">
      <hardwareInterface>hardware_interface/EffortJointInterface</hardwareInterface>
      <mechanicalReduction>1</mechanicalReduction>
    </actuator>
  </transmission>
  <!-- Lower leg -->
  <transmission name="forward_left_knee_trans">
    <type>transmission_interface/SimpleTransmission</type>
    <joint name="forward_left_knee_joint">
      <hardwareInterface>hardware_interface/EffortJointInterface</hardwareInterface>
    </joint>
    <actuator name="forward_left_knee_motor">
      <hardwareInterface>hardware_interface/EffortJointInterface</hardwareInterface>
      <mechanicalReduction>1</mechanicalReduction>
    </actuator>
  </transmission>
  <gazebo reference="forward_left_thigh_roll_joint">
    <provideFeedback>true</provideFeedback>
    <material>Gazebo/White</material>
  </gazebo>
  <gazebo>
    <plugin filename="libgazebo_ros_ft_sensor.so" name="forward_left_thigh_roll_joint">
      <robotNamespace>/quadruped/internal_wrench/</robotNamespace>
      <updateRate>100.0</updateRate>
      <topicName>forward_left_thigh_roll_joint</topicName>
      <jointName>forward_left_thigh_roll_joint</jointName>
    </plugin>
  </gazebo>
  <gazebo reference="forward_left_thigh_pitch_joint">
    <provideFeedback>true</provideFeedback>
    <material>Gazebo/White</material>
  </gazebo>
  <gazebo>
    <plugin filename="libgazebo_ros_ft_sensor.so" name="forward_left_thigh_pitch_joint">
      <robotNamespace>/quadruped/internal_wrench/</robotNamespace>
      <updateRate>100.0</updateRate>
      <topicName>forward_left_thigh_pitch_joint</topicName>
      <jointName>forward_left_thigh_pitch_joint</jointName>
    </plugin>
  </gazebo>
  <gazebo reference="forward_left_knee_joint">
    <provideFeedback>true</provideFeedback>
    <material>Gazebo/White</material>
  </gazebo>
  <gazebo>
    <plugin filename="libgazebo_ros_ft_sensor.so" name="forward_left_knee_joint">
      <robotNamespace>/quadruped/internal_wrench/</robotNamespace>
      <updateRate>100.0</updateRate>
      <topicName>forward_left_knee_joint</topicName>
      <jointName>forward_left_knee_joint</jointName>
    </plugin>
  </gazebo>
  <gazebo reference="forward_left_upper_leg">
    <kp>1000000.0</kp>
    <kd>100.0</kd>
    <mu1>1.5</mu1>
    <mu2>1.5</mu2>
    <fdir1>1 0 0</fdir1>
    <maxVel>1.0</maxVel>
    <minDepth>0.00</minDepth>
    <material>Gazebo/White</material>
  </gazebo>
  <gazebo reference="forward_left_lower_leg">
    <kp>1000000.0</kp>
    <kd>100.0</kd>
    <mu1>1.0</mu1>
    <mu2>1.0</mu2>
    <maxVel>1.0</maxVel>
    <maxContacts>1</maxContacts>
    <sensor name="forward_left_shin_contact_sensor" type="contact">
      <always_on>true</always_on>
      <update_rate>250.0</update_rate>
      <contact>
        <collision>forward_left_lowerleg_collision</collision>
      </contact>
      <plugin filename="libgazebo_ros_bumper.so" name="forward_left_shin_bumper">
        <bumperTopicName>/quadruped/forward_left_shin_bumper</bumperTopicName>
        <frameName>base_footprint</frameName>
      </plugin>
    </sensor>
    <material>Gazebo/White</material>
  </gazebo>
  <gazebo reference="forward_left_sole_sphere">
    <kp>1000000.0</kp>
    <kd>100.0</kd>
    <mu1>1.0</mu1>
    <mu2>1.0</mu2>
    <maxVel>1.0</maxVel>
    <maxContacts>1</maxContacts>
    <sensor name="forward_left_foot_contact_sensor" type="contact">
      <always_on>true</always_on>
      <update_rate>250.0</update_rate>
      <contact>
        <collision>forward_left_lowerleg_fixed_joint_lump__forward_left_foot_collision_1</collision>
      </contact>
      <plugin filename="libgazebo_ros_bumper.so" name="forward_left_foot_bumper">
        <bumperTopicName>/quadruped/forward_left_foot_bumper</bumperTopicName>
        <frameName>base_footprint</frameName>
        <robotNamespace>quadruped</robotNamespace>
      </plugin>
    </sensor>
    <material>Gazebo/White</material>
  </gazebo>
  <!--Joints-->
  <!-- joint between the thigh_roll_cylinder and pelvic -->
  <joint name="backward_right_thigh_roll_joint" type="revolute">
    <origin xyz="-0.7 -0.68 -0.1"/>
    <!-- 0.3 and 0.1 are the offset provided for the thigh_roll_cylinder from the front and centerline below-->
    <parent link="pelvis"/>
    <child link="backward_right_thigh_roll_cylinder"/>
    <axis xyz="1 0 0"/>
    <limit effort="300" lower="-1.0471975512" upper="0.261799387799" velocity="0.1"/>
    <dynamics damping="0.1" friction="0"/>
  </joint>
  <!-- fixed joint between the thigh_roll_cylinder and thigh_bwn_cylinder -->
  <joint name="backward_right_thigh_bwn_joint" type="fixed">
    <origin xyz="0 0 -0.115"/>
    <parent link="backward_right_thigh_roll_cylinder"/>
    <child link="backward_right_thigh_bwn_cylinder"/>
  </joint>
  <!-- the joint which allows the pitch motion of the thigh -->
  <joint name="backward_right_thigh_pitch_joint" type="revolute">
    <origin rpy="0 -0.523598775598 0" xyz="0 0 -0.095"/>
    <parent link="backward_right_thigh_bwn_cylinder"/>
    <child link="backward_right_thigh_pitch_cylinder"/>
    <axis xyz="0 1 0"/>
    <limit effort="300" lower="-1.5707963268" upper="0.523598775598" velocity="0.1"/>
    <dynamics damping="0.1" friction="0"/>
  </joint>
  <!-- the permanent joint connecting upper leg and the thigh_pitch_cylinder -->
  <joint name="backward_right_leg_thigh_joint" type="fixed">
    <origin xyz="0 0 -0.41"/>
    <parent link="backward_right_thigh_pitch_cylinder"/>
    <child link="backward_right_upper_leg"/>
  </joint>
  <!-- knee joint -->
  <joint name="backward_right_knee_joint" type="revolute">
    <origin rpy="0 1.308996939 0" xyz="0 0 -0.41"/>
    <parent link="backward_right_upper_leg"/>
    <child link="backward_right_knee_cylinder"/>
    <axis xyz="0 1 0"/>
    <limit effort="300" lower="-2.61799387799" upper="0.698131700798" velocity="0.1"/>
    <dynamics damping="0.1" friction="0"/>
  </joint>
  <!-- the permanent joint connecting the knee cylinder with the lower leg -->
  <joint name="backward_right_knee_fixed_joint" type="fixed">
    <origin xyz="0 0 -0.36"/>
    <parent link="backward_right_knee_cylinder"/>
    <child link="backward_right_lower_leg"/>
  </joint>
  <!-- the permanent joint connecting the sole and lower_leg -->
  <joint name="backward_right_sole_fixed_joint" type="fixed">
    <origin xyz="0 0 -0.37"/>
    <parent link="backward_right_lower_leg"/>
    <child link="backward_right_sole_sphere"/>
  </joint>
  <!-- Links -->
  <!--- link which allows the lateral motion of the link -->
  <link name="backward_right_thigh_roll_cylinder">
    <inertial>
      <mass value="0.1"/>
      <origin xyz="0 0 0"/>
      <inertia ixx="3.99988e-05" ixy="0" ixz="0" iyy="2e-05" iyz="0" izz="3.99988e-05"/>
    </inertial>
    <visual>
      <geometry>
        <cylinder length="0.2" radius="0.08"/>
      </geometry>
      <origin rpy="0 1.57079632679 0" xyz="0 0 0"/>
      <material name="red"/>
    </visual>
    <collision>
      <origin rpy="0 1.57079632679 0" xyz="0 0 0"/>
      <geometry>
        <cylinder length="0.2" radius="0.08"/>
      </geometry>
    </collision>
  </link>
  <!--- the link which joints the thigh_roll_cylinder and thigh_pitch_cylinder -->
  <link name="backward_right_thigh_bwn_cylinder">
    <inertial>
      <mass value="0.1"/>
      <origin xyz="0 0 0"/>
      <inertia ixx="3.99988e-05" ixy="0" ixz="0" iyy="3.99988e-05" iyz="0" izz="2e-05"/>
    </inertial>
    <visual>
      <geometry>
        <cylinder length="0.07" radius="0.03"/>
      </geometry>
      <origin xyz="0 0 0"/>
      <material name="red"/>
    </visual>
    <collision>
      <geometry>
        <cylinder length="0.07" radius="0.03"/>
      </geometry>
    </collision>
  </link>
  <!-- the link(cylinder) which is attached to the upper_leg -->
  <link name="backward_right_thigh_pitch_cylinder">
    <inertial>
      <mass value="0.1"/>
      <origin xyz="0 0 0"/>
      <inertia ixx="2e-05" ixy="0" ixz="0" iyy="3.99988e-05" iyz="0" izz="3.99988e-05"/>
    </inertial>
    <visual>
      <geometry>
        <cylinder length="0.2" radius="0.06"/>
      </geometry>
      <origin rpy="1.57079632679 0 0" xyz="0 0 0"/>
      <material name="red"/>
    </visual>
    <collision>
      <origin rpy="1.57079632679 0 0" xyz="0 0 0"/>
      <geometry>
        <cylinder length="0.2" radius="0.06"/>
      </geometry>
    </collision>
  </link>
  <!-- the upper leg -->
  <link name="backward_right_upper_leg">
    <inertial>
      <mass value="2.638"/>
      <origin xyz="0.150 0.026 0.0"/>
      <inertia ixx="0.0036" ixy="-0.003" ixz="0.0001" iyy="0.027" iyz="0.00002" izz="0.028"/>
    </inertial>
    <visual>
      <geometry>
        <cylinder length="0.7" radius="0.075"/>
      </geometry>
      <origin rpy="0 0 0" xyz="0 0 0"/>
      <material name="red"/>
    </visual>
    <collision>
      <geometry>
        <cylinder length="0.7" radius="0.075"/>
      </geometry>
    </collision>
  </link>
  <!-- the link(cylinder) at the knee which connects the upper and lower leg -->
  <link name="backward_right_knee_cylinder">
    <inertial>
      <mass value="0.1"/>
      <origin xyz="0 0 0"/>
      <inertia ixx="2e-05" ixy="0" ixz="0" iyy="3.99988e-05" iyz="0" izz="3.99988e-05"/>
    </inertial>
    <visual>
      <geometry>
        <cylinder length="0.2" radius="0.06"/>
      </geometry>
      <origin rpy="1.57079632679 0 0" xyz="0 0 0"/>
      <material name="red"/>
    </visual>
    <collision>
      <origin rpy="1.57079632679 0 0" xyz="0 0 0"/>
      <geometry>
        <cylinder length="0.2" radius="0.06"/>
      </geometry>
    </collision>
  </link>
  <!-- lower leg -->
  <link name="backward_right_lower_leg">
    <inertial>
      <mass value="0.881"/>
      <origin xyz="0.125 0.00004 -0.0001"/>
      <inertia ixx="0.0125" ixy="0.00006" ixz="-0.00001" iyy="0.01256" iyz="0" izz="0.0123"/>
    </inertial>
    <visual>
      <geometry>
        <cylinder length="0.6" radius="0.06"/>
      </geometry>
      <origin rpy="0 0 0" xyz="0 0 0"/>
      <material name="red"/>
    </visual>
    <collision>
      <geometry>
        <cylinder length="0.6" radius="0.06"/>
      </geometry>
    </collision>
  </link>
  <!-- the sphere which acts as the sole of the robot -->
  <link name="backward_right_sole_sphere">
    <inertial>
      <mass value="0.1"/>
      <origin xyz="0 0 0"/>
      <inertia ixx="1.6e-05" ixy="0" ixz="0" iyy="1.6e-05" iyz="0" izz="1.6e-05"/>
    </inertial>
    <visual>
      <geometry>
        <sphere radius="0.09"/>
      </geometry>
      <origin rpy="0 0 0" xyz="0 0 0"/>
      <material name="red"/>
    </visual>
    <collision>
      <geometry>
        <sphere radius="0.09"/>
      </geometry>
    </collision>
  </link>
  <!-- Hip assembly -->
  <transmission name="backward_right_thigh_roll_trans">
    <type>transmission_interface/SimpleTransmission</type>
    <joint name="backward_right_thigh_roll_joint">
      <hardwareInterface>hardware_interface/EffortJointInterface</hardwareInterface>
    </joint>
    <actuator name="backward_right_thigh_roll_motor">
      <hardwareInterface>hardware_interface/EffortJointInterface</hardwareInterface>
      <mechanicalReduction>1</mechanicalReduction>
    </actuator>
  </transmission>
  <!-- Upper leg -->
  <transmission name="backward_right_thigh_pitch_trans">
    <type>transmission_interface/SimpleTransmission</type>
    <joint name="backward_right_thigh_pitch_joint">
      <hardwareInterface>hardware_interface/EffortJointInterface</hardwareInterface>
    </joint>
    <actuator name="backward_right_thigh_pitch_motor">
      <hardwareInterface>hardware_interface/EffortJointInterface</hardwareInterface>
      <mechanicalReduction>1</mechanicalReduction>
    </actuator>
  </transmission>
  <!-- Lower leg -->
  <transmission name="backward_right_knee_trans">
    <type>transmission_interface/SimpleTransmission</type>
    <joint name="backward_right_knee_joint">
      <hardwareInterface>hardware_interface/EffortJointInterface</hardwareInterface>
    </joint>
    <actuator name="backward_right_knee_motor">
      <hardwareInterface>hardware_interface/EffortJointInterface</hardwareInterface>
      <mechanicalReduction>1</mechanicalReduction>
    </actuator>
  </transmission>
  <gazebo reference="backward_right_thigh_roll_joint">
    <provideFeedback>true</provideFeedback>
    <material>Gazebo/White</material>
  </gazebo>
  <gazebo>
    <plugin filename="libgazebo_ros_ft_sensor.so" name="backward_right_thigh_roll_joint">
      <robotNamespace>/quadruped/internal_wrench/</robotNamespace>
      <updateRate>100.0</updateRate>
      <topicName>backward_right_thigh_roll_joint</topicName>
      <jointName>backward_right_thigh_roll_joint</jointName>
    </plugin>
  </gazebo>
  <gazebo reference="backward_right_thigh_pitch_joint">
    <provideFeedback>true</provideFeedback>
    <material>Gazebo/White</material>
  </gazebo>
  <gazebo>
    <plugin filename="libgazebo_ros_ft_sensor.so" name="backward_right_thigh_pitch_joint">
      <robotNamespace>/quadruped/internal_wrench/</robotNamespace>
      <updateRate>100.0</updateRate>
      <topicName>backward_right_thigh_pitch_joint</topicName>
      <jointName>backward_right_thigh_pitch_joint</jointName>
    </plugin>
  </gazebo>
  <gazebo reference="backward_right_knee_joint">
    <provideFeedback>true</provideFeedback>
    <material>Gazebo/White</material>
  </gazebo>
  <gazebo>
    <plugin filename="libgazebo_ros_ft_sensor.so" name="backward_right_knee_joint">
      <robotNamespace>/quadruped/internal_wrench/</robotNamespace>
      <updateRate>100.0</updateRate>
      <topicName>backward_right_knee_joint</topicName>
      <jointName>backward_right_knee_joint</jointName>
    </plugin>
  </gazebo>
  <gazebo reference="backward_right_upper_leg">
    <kp>1000000.0</kp>
    <kd>100.0</kd>
    <mu1>1.5</mu1>
    <mu2>1.5</mu2>
    <fdir1>1 0 0</fdir1>
    <maxVel>1.0</maxVel>
    <minDepth>0.00</minDepth>
    <material>Gazebo/White</material>
  </gazebo>
  <gazebo reference="backward_right_lower_leg">
    <kp>1000000.0</kp>
    <kd>100.0</kd>
    <mu1>1.0</mu1>
    <mu2>1.0</mu2>
    <maxVel>1.0</maxVel>
    <maxContacts>1</maxContacts>
    <sensor name="backward_right_shin_contact_sensor" type="contact">
      <always_on>true</always_on>
      <update_rate>250.0</update_rate>
      <contact>
        <collision>backward_right_lowerleg_collision</collision>
      </contact>
      <plugin filename="libgazebo_ros_bumper.so" name="backward_right_shin_bumper">
        <bumperTopicName>/quadruped/backward_right_shin_bumper</bumperTopicName>
        <frameName>base_footprint</frameName>
      </plugin>
    </sensor>
    <material>Gazebo/White</material>
  </gazebo>
  <gazebo reference="backward_right_sole_sphere">
    <kp>1000000.0</kp>
    <kd>100.0</kd>
    <mu1>1.0</mu1>
    <mu2>1.0</mu2>
    <maxVel>1.0</maxVel>
    <maxContacts>1</maxContacts>
    <sensor name="backward_right_foot_contact_sensor" type="contact">
      <always_on>true</always_on>
      <update_rate>250.0</update_rate>
      <contact>
        <collision>backward_right_lowerleg_fixed_joint_lump__backward_right_foot_collision_1</collision>
      </contact>
      <plugin filename="libgazebo_ros_bumper.so" name="backward_right_foot_bumper">
        <bumperTopicName>/quadruped/backward_right_foot_bumper</bumperTopicName>
        <frameName>base_footprint</frameName>
        <robotNamespace>quadruped</robotNamespace>
      </plugin>
    </sensor>
    <material>Gazebo/White</material>
  </gazebo>
  <!--Joints-->
  <!-- joint between the thigh_roll_cylinder and pelvic -->
  <joint name="backward_left_thigh_roll_joint" type="revolute">
    <origin xyz="-0.7 0.68 -0.1"/>
    <!-- 0.3 and 0.1 are the offset provided for the thigh_roll_cylinder from the front and centerline below-->
    <parent link="pelvis"/>
    <child link="backward_left_thigh_roll_cylinder"/>
    <axis xyz="1 0 0"/>
    <limit effort="300" lower="-0.261799387799" upper="1.0471975512" velocity="0.1"/>
    <dynamics damping="0.1" friction="0"/>
  </joint>
  <!-- fixed joint between the thigh_roll_cylinder and thigh_bwn_cylinder -->
  <joint name="backward_left_thigh_bwn_joint" type="fixed">
    <origin xyz="0 0 -0.115"/>
    <parent link="backward_left_thigh_roll_cylinder"/>
    <child link="backward_left_thigh_bwn_cylinder"/>
  </joint>
  <!-- the joint which allows the pitch motion of the thigh -->
  <joint name="backward_left_thigh_pitch_joint" type="revolute">
    <origin rpy="0 -0.523598775598 0" xyz="0 0 -0.095"/>
    <parent link="backward_left_thigh_bwn_cylinder"/>
    <child link="backward_left_thigh_pitch_cylinder"/>
    <axis xyz="0 1 0"/>
    <limit effort="300" lower="-1.5707963268" upper="0.523598775598" velocity="0.1"/>
    <dynamics damping="0.1" friction="0"/>
  </joint>
  <!-- the permanent joint connecting upper leg and the thigh_pitch_cylinder -->
  <joint name="backward_left_leg_thigh_joint" type="fixed">
    <origin xyz="0 0 -0.41"/>
    <parent link="backward_left_thigh_pitch_cylinder"/>
    <child link="backward_left_upper_leg"/>
  </joint>
  <!-- knee joint -->
  <joint name="backward_left_knee_joint" type="revolute">
    <origin rpy="0 1.308996939 0" xyz="0 0 -0.41"/>
    <parent link="backward_left_upper_leg"/>
    <child link="backward_left_knee_cylinder"/>
    <axis xyz="0 1 0"/>
    <limit effort="300" lower="-2.61799387799" upper="0.698131700798" velocity="0.1"/>
    <dynamics damping="0.1" friction="0"/>
  </joint>
  <!-- the permanent joint connecting the knee cylinder with the lower leg -->
  <joint name="backward_left_knee_fixed_joint" type="fixed">
    <origin xyz="0 0 -0.36"/>
    <parent link="backward_left_knee_cylinder"/>
    <child link="backward_left_lower_leg"/>
  </joint>
  <!-- the permanent joint connecting the sole and lower_leg -->
  <joint name="backward_left_sole_fixed_joint" type="fixed">
    <origin xyz="0 0 -0.37"/>
    <parent link="backward_left_lower_leg"/>
    <child link="backward_left_sole_sphere"/>
  </joint>
  <!-- Links -->
  <!--- link which allows the lateral motion of the link -->
  <link name="backward_left_thigh_roll_cylinder">
    <inertial>
      <mass value="0.1"/>
      <origin xyz="0 0 0"/>
      <inertia ixx="3.99988e-05" ixy="0" ixz="0" iyy="2e-05" iyz="0" izz="3.99988e-05"/>
    </inertial>
    <visual>
      <geometry>
        <cylinder length="0.2" radius="0.08"/>
      </geometry>
      <origin rpy="0 1.57079632679 0" xyz="0 0 0"/>
      <material name="red"/>
    </visual>
    <collision>
      <origin rpy="0 1.57079632679 0" xyz="0 0 0"/>
      <geometry>
        <cylinder length="0.2" radius="0.08"/>
      </geometry>
    </collision>
  </link>
  <!--- the link which joints the thigh_roll_cylinder and thigh_pitch_cylinder -->
  <link name="backward_left_thigh_bwn_cylinder">
    <inertial>
      <mass value="0.1"/>
      <origin xyz="0 0 0"/>
      <inertia ixx="3.99988e-05" ixy="0" ixz="0" iyy="3.99988e-05" iyz="0" izz="2e-05"/>
    </inertial>
    <visual>
      <geometry>
        <cylinder length="0.07" radius="0.03"/>
      </geometry>
      <origin xyz="0 0 0"/>
      <material name="red"/>
    </visual>
    <collision>
      <geometry>
        <cylinder length="0.07" radius="0.03"/>
      </geometry>
    </collision>
  </link>
  <!-- the link(cylinder) which is attached to the upper_leg -->
  <link name="backward_left_thigh_pitch_cylinder">
    <inertial>
      <mass value="0.1"/>
      <origin xyz="0 0 0"/>
      <inertia ixx="2e-05" ixy="0" ixz="0" iyy="3.99988e-05" iyz="0" izz="3.99988e-05"/>
    </inertial>
    <visual>
      <geometry>
        <cylinder length="0.2" radius="0.06"/>
      </geometry>
      <origin rpy="1.57079632679 0 0" xyz="0 0 0"/>
      <material name="red"/>
    </visual>
    <collision>
      <origin rpy="1.57079632679 0 0" xyz="0 0 0"/>
      <geometry>
        <cylinder length="0.2" radius="0.06"/>
      </geometry>
    </collision>
  </link>
  <!-- the upper leg -->
  <link name="backward_left_upper_leg">
    <inertial>
      <mass value="2.638"/>
      <origin xyz="0.150 0.026 0.0"/>
      <inertia ixx="0.0036" ixy="-0.003" ixz="0.0001" iyy="0.027" iyz="0.00002" izz="0.028"/>
    </inertial>
    <visual>
      <geometry>
        <cylinder length="0.7" radius="0.075"/>
      </geometry>
      <origin rpy="0 0 0" xyz="0 0 0"/>
      <material name="red"/>
    </visual>
    <collision>
      <geometry>
        <cylinder length="0.7" radius="0.075"/>
      </geometry>
    </collision>
  </link>
  <!-- the link(cylinder) at the knee which connects the upper and lower leg -->
  <link name="backward_left_knee_cylinder">
    <inertial>
      <mass value="0.1"/>
      <origin xyz="0 0 0"/>
      <inertia ixx="2e-05" ixy="0" ixz="0" iyy="3.99988e-05" iyz="0" izz="3.99988e-05"/>
    </inertial>
    <visual>
      <geometry>
        <cylinder length="0.2" radius="0.06"/>
      </geometry>
      <origin rpy="1.57079632679 0 0" xyz="0 0 0"/>
      <material name="red"/>
    </visual>
    <collision>
      <origin rpy="1.57079632679 0 0" xyz="0 0 0"/>
      <geometry>
        <cylinder length="0.2" radius="0.06"/>
      </geometry>
    </collision>
  </link>
  <!-- lower leg -->
  <link name="backward_left_lower_leg">
    <inertial>
      <mass value="0.881"/>
      <origin xyz="0.125 0.00004 -0.0001"/>
      <inertia ixx="0.0125" ixy="0.00006" ixz="-0.00001" iyy="0.01256" iyz="0" izz="0.0123"/>
    </inertial>
    <visual>
      <geometry>
        <cylinder length="0.6" radius="0.06"/>
      </geometry>
      <origin rpy="0 0 0" xyz="0 0 0"/>
      <material name="red"/>
    </visual>
    <collision>
      <geometry>
        <cylinder length="0.6" radius="0.06"/>
      </geometry>
    </collision>
  </link>
  <!-- the sphere which acts as the sole of the robot -->
  <link name="backward_left_sole_sphere">
    <inertial>
      <mass value="0.1"/>
      <origin xyz="0 0 0"/>
      <inertia ixx="1.6e-05" ixy="0" ixz="0" iyy="1.6e-05" iyz="0" izz="1.6e-05"/>
    </inertial>
    <visual>
      <geometry>
        <sphere radius="0.09"/>
      </geometry>
      <origin rpy="0 0 0" xyz="0 0 0"/>
      <material name="red"/>
    </visual>
    <collision>
      <geometry>
        <sphere radius="0.09"/>
      </geometry>
    </collision>
  </link>
  <!-- Hip assembly -->
  <transmission name="backward_left_thigh_roll_trans">
    <type>transmission_interface/SimpleTransmission</type>
    <joint name="backward_left_thigh_roll_joint">
      <hardwareInterface>hardware_interface/EffortJointInterface</hardwareInterface>
    </joint>
    <actuator name="backward_left_thigh_roll_motor">
      <hardwareInterface>hardware_interface/EffortJointInterface</hardwareInterface>
      <mechanicalReduction>1</mechanicalReduction>
    </actuator>
  </transmission>
  <!-- Upper leg -->
  <transmission name="backward_left_thigh_pitch_trans">
    <type>transmission_interface/SimpleTransmission</type>
    <joint name="backward_left_thigh_pitch_joint">
      <hardwareInterface>hardware_interface/EffortJointInterface</hardwareInterface>
    </joint>
    <actuator name="backward_left_thigh_pitch_motor">
      <hardwareInterface>hardware_interface/EffortJointInterface</hardwareInterface>
      <mechanicalReduction>1</mechanicalReduction>
    </actuator>
  </transmission>
  <!-- Lower leg -->
  <transmission name="backward_left_knee_trans">
    <type>transmission_interface/SimpleTransmission</type>
    <joint name="backward_left_knee_joint">
      <hardwareInterface>hardware_interface/EffortJointInterface</hardwareInterface>
    </joint>
    <actuator name="backward_left_knee_motor">
      <hardwareInterface>hardware_interface/EffortJointInterface</hardwareInterface>
      <mechanicalReduction>1</mechanicalReduction>
    </actuator>
  </transmission>
  <gazebo reference="backward_left_thigh_roll_joint">
    <provideFeedback>true</provideFeedback>
    <material>Gazebo/White</material>
  </gazebo>
  <gazebo>
    <plugin filename="libgazebo_ros_ft_sensor.so" name="backward_left_thigh_roll_joint">
      <robotNamespace>/quadruped/internal_wrench/</robotNamespace>
      <updateRate>100.0</updateRate>
      <topicName>backward_left_thigh_roll_joint</topicName>
      <jointName>backward_left_thigh_roll_joint</jointName>
    </plugin>
  </gazebo>
  <gazebo reference="backward_left_thigh_pitch_joint">
    <provideFeedback>true</provideFeedback>
    <material>Gazebo/White</material>
  </gazebo>
  <gazebo>
    <plugin filename="libgazebo_ros_ft_sensor.so" name="backward_left_thigh_pitch_joint">
      <robotNamespace>/quadruped/internal_wrench/</robotNamespace>
      <updateRate>100.0</updateRate>
      <topicName>backward_left_thigh_pitch_joint</topicName>
      <jointName>backward_left_thigh_pitch_joint</jointName>
    </plugin>
  </gazebo>
  <gazebo reference="backward_left_knee_joint">
    <provideFeedback>true</provideFeedback>
    <material>Gazebo/White</material>
  </gazebo>
  <gazebo>
    <plugin filename="libgazebo_ros_ft_sensor.so" name="backward_left_knee_joint">
      <robotNamespace>/quadruped/internal_wrench/</robotNamespace>
      <updateRate>100.0</updateRate>
      <topicName>backward_left_knee_joint</topicName>
      <jointName>backward_left_knee_joint</jointName>
    </plugin>
  </gazebo>
  <gazebo reference="backward_left_upper_leg">
    <kp>1000000.0</kp>
    <kd>100.0</kd>
    <mu1>1.5</mu1>
    <mu2>1.5</mu2>
    <fdir1>1 0 0</fdir1>
    <maxVel>1.0</maxVel>
    <minDepth>0.00</minDepth>
    <material>Gazebo/White</material>
  </gazebo>
  <gazebo reference="backward_left_lower_leg">
    <kp>1000000.0</kp>
    <kd>100.0</kd>
    <mu1>1.0</mu1>
    <mu2>1.0</mu2>
    <maxVel>1.0</maxVel>
    <maxContacts>1</maxContacts>
    <sensor name="backward_left_shin_contact_sensor" type="contact">
      <always_on>true</always_on>
      <update_rate>250.0</update_rate>
      <contact>
        <collision>backward_left_lowerleg_collision</collision>
      </contact>
      <plugin filename="libgazebo_ros_bumper.so" name="backward_left_shin_bumper">
        <bumperTopicName>/quadruped/backward_left_shin_bumper</bumperTopicName>
        <frameName>base_footprint</frameName>
      </plugin>
    </sensor>
    <material>Gazebo/White</material>
  </gazebo>
  <gazebo reference="backward_left_sole_sphere">
    <kp>1000000.0</kp>
    <kd>100.0</kd>
    <mu1>1.0</mu1>
    <mu2>1.0</mu2>
    <maxVel>1.0</maxVel>
    <maxContacts>1</maxContacts>
    <sensor name="backward_left_foot_contact_sensor" type="contact">
      <always_on>true</always_on>
      <update_rate>250.0</update_rate>
      <contact>
        <collision>backward_left_lowerleg_fixed_joint_lump__backward_left_foot_collision_1</collision>
      </contact>
      <plugin filename="libgazebo_ros_bumper.so" name="backward_left_foot_bumper">
        <bumperTopicName>/quadruped/backward_left_foot_bumper</bumperTopicName>
        <frameName>base_footprint</frameName>
        <robotNamespace>quadruped</robotNamespace>
      </plugin>
    </sensor>
    <material>Gazebo/White</material>
  </gazebo>
  <!-- Joints -->
  <joint name="pelvis_shoulder_fixed_joint" type="fixed">
    <origin xyz="0.8 0 0.4"/>
    <parent link="pelvis"/>
    <child link="spine_cylinder"/>
  </joint>
  <joint name="shoulder_twist" type="fixed">
    <origin xyz="0 0 0.3"/>
    <parent link="spine_cylinder"/>
    <child link="shoulder"/>
    <axis xyz="0 0 1"/>
    <limit effort="300" lower="-3.14" upper="3.14" velocity="0.1"/>
  </joint>
  <!-- Links -->
  <link name="spine_cylinder">
    <visual>
      <geometry>
        <cylinder length="0.3" radius="0.08"/>
      </geometry>
      <origin xyz="0 0 0"/>
      <material name="red"/>
    </visual>
    <collision>
      <geometry>
        <cylinder length="0.3" radius="0.08"/>
      </geometry>
    </collision>
  </link>
  <link name="shoulder">
    <visual>
      <geometry>
        <box size="1.2 0.5 0.3"/>
      </geometry>
      <origin xyz="0 0 0"/>
      <material name="red"/>
    </visual>
    <collision>
      <geometry>
        <box size="1.2 0.5 0.3"/>
      </geometry>
    </collision>
  </link>
  <!-- Joints -->
  <joint name="left_shoulder_pitch_joint" type="revolute">
    <origin xyz="0 -0.65 0"/>
    <parent link="shoulder"/>
    <child link="left_shoulder_pitch_cylinder"/>
    <axis xyz="0 1 0"/>
    <limit effort="300" lower="-3.14" upper="3.14" velocity="0.1"/>
  </joint>
  <joint name="left_shoulder_roll_joint" type="revolute">
    <origin rpy="0 0.3 0" xyz="0 -0.15 0"/>
    <parent link="left_shoulder_pitch_cylinder"/>
    <child link="left_shoulder_roll_cylinder"/>
    <axis xyz="1 0 0"/>
    <limit effort="300" lower="-3.14" upper="3.14" velocity="0.1"/>
  </joint>
  <joint name="left_shoulder_fixed_joint" type="fixed">
    <origin xyz="0 0 -0.25"/>
    <parent link="left_shoulder_roll_cylinder"/>
    <child link="left_shoulder_bwn_cylinder"/>
  </joint>
  <joint name="left_shoulder_yaw_joint" type="revolute">
    <origin xyz="0 0 -0.35"/>
    <parent link="left_shoulder_bwn_cylinder"/>
    <child link="left_shoulder_yaw_cylinder"/>
    <axis xyz="0 0 1"/>
    <limit effort="300" lower="-3.14" upper="3.14" velocity="0.1"/>
  </joint>
  <joint name="left_elbow_joint" type="revolute">
    <origin rpy="0 -0.3 0" xyz="0 0 -0.275"/>
    <parent link="left_shoulder_yaw_cylinder"/>
    <child link="left_elbow_cylinder"/>
    <axis xyz="0 1 0"/>
    <limit effort="300" lower="-3.14" upper="3.14" velocity="0.1"/>
  </joint>
  <joint name="left_forearm_fixed_joint" type="fixed">
    <origin xyz="0 0 -0.275"/>
    <parent link="left_elbow_cylinder"/>
    <child link="left_forearm_cylinder"/>
  </joint>
  <joint name="left_wrist_joint" type="fixed">
    <origin xyz="0 0 -0.325"/>
    <parent link="left_forearm_cylinder"/>
    <child link="left_wrist_cylinder"/>
    <axis xyz="0 0 1"/>
    <limit effort="300" lower="-3.14" upper="3.14" velocity="0.1"/>
  </joint>
  <joint name="left_gripper_fixed_joint" type="fixed">
    <origin xyz="0 0 -0.135"/>
    <parent link="left_wrist_cylinder"/>
    <child link="left_gripper_fixed_link"/>
  </joint>
  <joint name="left_finger_joint1" type="revolute">
    <parent link="left_gripper_fixed_link"/>
    <child link="left_gripper_finger_link1"/>
    <origin xyz="0.0 0 0"/>
    <axis xyz="1 0 0"/>
    <limit effort="1" lower="-0.09" upper="0" velocity="1.0"/>
  </joint>
  <joint name="left_finger_joint2" type="revolute">
    <parent link="left_gripper_fixed_link"/>
    <child link="left_gripper_finger_link2"/>
    <origin xyz="0.0 0 0"/>
    <axis xyz="1 0 0"/>
    <limit effort="1" lower="0" upper="0.09" velocity="1.0"/>
  </joint>
  <!-- Links -->
  <link name="left_shoulder_pitch_cylinder">
    <visual>
      <geometry>
        <cylinder length="0.1" radius="0.08"/>
      </geometry>
      <origin rpy="0 1.57079632679 0" xyz="0 0 0"/>
      <material name="red"/>
    </visual>
    <collision>
      <origin rpy="0 1.57079632679 0" xyz="0 0 0"/>
      <geometry>
        <cylinder length="0.1" radius="0.08"/>
      </geometry>
    </collision>
  </link>
  <link name="left_shoulder_roll_cylinder">
    <visual>
      <geometry>
        <cylinder length="0.25" radius="0.1"/>
      </geometry>
      <origin rpy="1.57079632679 0 0" xyz="0 0 0"/>
      <material name="red"/>
    </visual>
    <collision>
      <origin rpy="1.57079632679 0 0" xyz="0 0 0"/>
      <geometry>
        <cylinder length="0.25" radius="0.1"/>
      </geometry>
    </collision>
  </link>
  <link name="left_shoulder_bwn_cylinder">
    <visual>
      <geometry>
        <cylinder length="0.3" radius="0.1"/>
      </geometry>
      <origin xyz="0 0 0"/>
      <material name="red"/>
    </visual>
    <collision>
      <geometry>
        <cylinder length="0.3" radius="0.1"/>
      </geometry>
    </collision>
  </link>
  <link name="left_shoulder_yaw_cylinder">
    <visual>
      <geometry>
        <cylinder length="0.4" radius="0.1"/>
      </geometry>
      <origin xyz="0 0 0"/>
      <material name="red"/>
    </visual>
    <collision>
      <geometry>
        <cylinder length="0.4" radius="0.1"/>
      </geometry>
    </collision>
  </link>
  <link name="left_elbow_cylinder">
    <visual>
      <geometry>
        <cylinder length="0.15" radius="0.075"/>
      </geometry>
      <origin rpy="1.57079632679 0 0" xyz="0 0 0"/>
      <material name="red"/>
    </visual>
    <collision>
      <origin rpy="1.57079632679 0 0" xyz="0 0 0"/>
      <geometry>
        <cylinder length="0.15" radius="0.075"/>
      </geometry>
    </collision>
  </link>
  <link name="left_forearm_cylinder">
    <visual>
      <geometry>
        <cylinder length="0.4" radius="0.075"/>
      </geometry>
      <origin xyz="0 0 0"/>
      <material name="red"/>
    </visual>
    <collision>
      <geometry>
        <cylinder length="0.4" radius="0.075"/>
      </geometry>
    </collision>
  </link>
  <link name="left_wrist_cylinder">
    <visual>
      <geometry>
        <cylinder length="0.25" radius="0.075"/>
      </geometry>
      <origin xyz="0 0 0"/>
      <material name="red"/>
    </visual>
    <collision>
      <geometry>
        <cylinder length="0.25" radius="0.075"/>
      </geometry>
    </collision>
  </link>
  <link name="left_gripper_fixed_link">
    <visual>
      <geometry>
        <box size="0.2 0.07 0.02"/>
      </geometry>
      <origin xyz="0 0 0"/>
      <material name="red"/>
    </visual>
    <collision>
      <geometry>
        <box size="0.2 0.07 0.02"/>
      </geometry>
    </collision>
  </link>
  <link name="left_gripper_finger_link1">
    <visual>
      <geometry>
        <box size="0.02 0.07 0.2"/>
      </geometry>
      <origin xyz="0.09 0 -0.1"/>
      <material name="red"/>
    </visual>
    <collision>
      <origin xyz="0.09 0 -0.1"/>
      <geometry>
        <box size="0.02 0.07 0.2"/>
      </geometry>
    </collision>
  </link>
  <link name="left_gripper_finger_link2">
    <visual>
      <geometry>
        <box size="0.02 0.07 0.2"/>
      </geometry>
      <origin xyz="-0.09 0 -0.1"/>
      <material name="red"/>
    </visual>
    <collision>
      <origin xyz="-0.09 0 -0.1"/>
      <geometry>
        <box size="0.02 0.07 0.2"/>
      </geometry>
    </collision>
  </link>
  <!-- Joints -->
  <joint name="right_shoulder_pitch_joint" type="revolute">
    <origin xyz="0 0.65 0"/>
    <parent link="shoulder"/>
    <child link="right_shoulder_pitch_cylinder"/>
    <axis xyz="0 1 0"/>
    <limit effort="300" lower="-3.14" upper="3.14" velocity="0.1"/>
  </joint>
  <joint name="right_shoulder_roll_joint" type="revolute">
    <origin rpy="0 -0.3 0" xyz="0 0.15 0"/>
    <parent link="right_shoulder_pitch_cylinder"/>
    <child link="right_shoulder_roll_cylinder"/>
    <axis xyz="1 0 0"/>
    <limit effort="300" lower="-3.14" upper="3.14" velocity="0.1"/>
  </joint>
  <joint name="right_shoulder_fixed_joint" type="fixed">
    <origin xyz="0 0 -0.25"/>
    <parent link="right_shoulder_roll_cylinder"/>
    <child link="right_shoulder_bwn_cylinder"/>
  </joint>
  <joint name="right_shoulder_yaw_joint" type="revolute">
    <origin xyz="0 0 -0.35"/>
    <parent link="right_shoulder_bwn_cylinder"/>
    <child link="right_shoulder_yaw_cylinder"/>
    <axis xyz="0 0 1"/>
    <limit effort="300" lower="-3.14" upper="3.14" velocity="0.1"/>
  </joint>
  <joint name="right_elbow_joint" type="revolute">
    <origin rpy="0 0.3 0" xyz="0 0 -0.275"/>
    <parent link="right_shoulder_yaw_cylinder"/>
    <child link="right_elbow_cylinder"/>
    <axis xyz="0 1 0"/>
    <limit effort="300" lower="-3.14" upper="3.14" velocity="0.1"/>
  </joint>
  <joint name="right_forearm_fixed_joint" type="fixed">
    <origin xyz="0 0 -0.275"/>
    <parent link="right_elbow_cylinder"/>
    <child link="right_forearm_cylinder"/>
  </joint>
  <joint name="right_wrist_joint" type="fixed">
    <origin xyz="0 0 -0.325"/>
    <parent link="right_forearm_cylinder"/>
    <child link="right_wrist_cylinder"/>
    <axis xyz="0 0 1"/>
    <limit effort="300" lower="-3.14" upper="3.14" velocity="0.1"/>
  </joint>
  <joint name="right_gripper_fixed_joint" type="fixed">
    <origin xyz="0 0 -0.135"/>
    <parent link="right_wrist_cylinder"/>
    <child link="right_gripper_fixed_link"/>
  </joint>
  <joint name="right_finger_joint1" type="revolute">
    <parent link="right_gripper_fixed_link"/>
    <child link="right_gripper_finger_link1"/>
    <origin xyz="0.0 0 0"/>
    <axis xyz="1 0 0"/>
    <limit effort="1" lower="-0.09" upper="0" velocity="1.0"/>
  </joint>
  <joint name="right_finger_joint2" type="revolute">
    <parent link="right_gripper_fixed_link"/>
    <child link="right_gripper_finger_link2"/>
    <origin xyz="0.0 0 0"/>
    <axis xyz="1 0 0"/>
    <limit effort="1" lower="0" upper="0.09" velocity="1.0"/>
  </joint>
  <!-- Links -->
  <link name="right_shoulder_pitch_cylinder">
    <visual>
      <geometry>
        <cylinder length="0.1" radius="0.08"/>
      </geometry>
      <origin rpy="0 1.57079632679 0" xyz="0 0 0"/>
      <material name="red"/>
    </visual>
    <collision>
      <origin rpy="0 1.57079632679 0" xyz="0 0 0"/>
      <geometry>
        <cylinder length="0.1" radius="0.08"/>
      </geometry>
    </collision>
  </link>
  <link name="right_shoulder_roll_cylinder">
    <visual>
      <geometry>
        <cylinder length="0.25" radius="0.1"/>
      </geometry>
      <origin rpy="1.57079632679 0 0" xyz="0 0 0"/>
      <material name="red"/>
    </visual>
    <collision>
      <origin rpy="1.57079632679 0 0" xyz="0 0 0"/>
      <geometry>
        <cylinder length="0.25" radius="0.1"/>
      </geometry>
    </collision>
  </link>
  <link name="right_shoulder_bwn_cylinder">
    <visual>
      <geometry>
        <cylinder length="0.3" radius="0.1"/>
      </geometry>
      <origin xyz="0 0 0"/>
      <material name="red"/>
    </visual>
    <collision>
      <geometry>
        <cylinder length="0.3" radius="0.1"/>
      </geometry>
    </collision>
  </link>
  <link name="right_shoulder_yaw_cylinder">
    <visual>
      <geometry>
        <cylinder length="0.4" radius="0.1"/>
      </geometry>
      <origin xyz="0 0 0"/>
      <material name="red"/>
    </visual>
    <collision>
      <geometry>
        <cylinder length="0.4" radius="0.1"/>
      </geometry>
    </collision>
  </link>
  <link name="right_elbow_cylinder">
    <visual>
      <geometry>
        <cylinder length="0.15" radius="0.075"/>
      </geometry>
      <origin rpy="1.57079632679 0 0" xyz="0 0 0"/>
      <material name="red"/>
    </visual>
    <collision>
      <origin rpy="1.57079632679 0 0" xyz="0 0 0"/>
      <geometry>
        <cylinder length="0.15" radius="0.075"/>
      </geometry>
    </collision>
  </link>
  <link name="right_forearm_cylinder">
    <visual>
      <geometry>
        <cylinder length="0.4" radius="0.075"/>
      </geometry>
      <origin xyz="0 0 0"/>
      <material name="red"/>
    </visual>
    <collision>
      <geometry>
        <cylinder length="0.4" radius="0.075"/>
      </geometry>
    </collision>
  </link>
  <link name="right_wrist_cylinder">
    <visual>
      <geometry>
        <cylinder length="0.25" radius="0.075"/>
      </geometry>
      <origin xyz="0 0 0"/>
      <material name="red"/>
    </visual>
    <collision>
      <geometry>
        <cylinder length="0.25" radius="0.075"/>
      </geometry>
    </collision>
  </link>
  <link name="right_gripper_fixed_link">
    <visual>
      <geometry>
        <box size="0.2 0.07 0.02"/>
      </geometry>
      <origin xyz="0 0 0"/>
      <material name="red"/>
    </visual>
    <collision>
      <geometry>
        <box size="0.2 0.07 0.02"/>
      </geometry>
    </collision>
  </link>
  <link name="right_gripper_finger_link1">
    <visual>
      <geometry>
        <box size="0.02 0.07 0.2"/>
      </geometry>
      <origin xyz="0.09 0 -0.1"/>
      <material name="red"/>
    </visual>
    <collision>
      <origin xyz="0.09 0 -0.1"/>
      <geometry>
        <box size="0.02 0.07 0.2"/>
      </geometry>
    </collision>
  </link>
  <link name="right_gripper_finger_link2">
    <visual>
      <geometry>
        <box size="0.02 0.07 0.2"/>
      </geometry>
      <origin xyz="-0.09 0 -0.1"/>
      <material name="red"/>
    </visual>
    <collision>
      <origin xyz="-0.09 0 -0.1"/>
      <geometry>
        <box size="0.02 0.07 0.2"/>
      </geometry>
    </collision>
  </link>
</robot>
